Workbook
Name Identical_Circuits__1_2: 'R-410A_Calculator'!$C$6

Sheet Changelog
A1: Rev | B1: Date | C1: By | D1: Includes
A2: D | B2: 41960 | C2: JWE | D2: Updated rep list. Checked table values in ASHRAE 2014 Refrigebook for suction, discharge, and Liquid line Capacities
A3: F | B3: 42377 | C3: JWE | D3: Updated Rep list. Included Suction Trap diagram
A4: G | B4: 42510 | C4: JWE | D4: Updated recommended oil to add to system in piping notes
A5: H | B5: 42485 | C5: JWE | D5: Updated dropdown menus to include Digital scroll option. Added CDI/Updated to rep roster
A6: I | B6: 43515 | C6: JWE | D6: Added 60ft riser details and changed HGBP logic to consider minimum valve position
A7: J | B7: 43563 | C7: JWE | D7: Updated dropdown menu to have new single circuit options
A8: 6 | B8: TBD | C8: JWE | D8: Update Discharge line logic (see notes); Add Refrigerant charge estiamte (3rd page); Update notes to say Max combined suction riser to 60, trap and bleed with diagram

Sheet R-410A_Calculator
A1: REFRIGERANT PIPING REVIEW | M1: Circuit #+MM:M | N1: Superheat | O1: Condensing Temp | P1: Discharge Temp | Q1: Fittings | R1: Refrigeration | V1: Reps | X1: RCS | Y1: Capacity | Z1: Staging
M2: #1 | N2: oF | O2: oF | P2: oF | Q2: Click here to select fitting. | R2: =((D10*12000)/(120.83-28.85))/0.7 -> 1658.7457 | S2: lb/h min. refrigerant flow @ 45°F SST
A3: Job Name: | C3: 20241002001 - Inspira IMC Mannington Pharmacy | H3: Rep Office: | I3: TriState HVAC Equipment, LLP | M3: #2 | N3: 10 | O3: Select | Q3: 90° Std Elbow | R3: 71.51 | S3: lb/c.f. density of liquid refrigerant @ 45°F | V3: Air Cond. Equip. Sales, Inc. | X3: RCS06F-079 | Y3: Nominal = 6.5 tons (CKT#1 = 1 - 6.5 ton compressor) | Z3: Staging = 0-100
A4: Job Description: | C4: DCSA040 (fixed speeds on both circuit) coupled with Skyline DXG12C12 | H4: Sales Person: | I4: Mark Lombardi | M4: Identical Circuits (1=2) | O4: 80 | Q4: 90° Long Radius Elbow | R4: =R2/(R3*60) -> 0.38659994 | S4: CFM of liquid refrigerant | V4: Air Reps | X4: RCS07G-091 | Y4: Nominal = 7.5 tons (CKT#1 = 1 - 7.5 ton compressor) | Z4: Staging = 0-100
A5: Model Number: | H5: Date: | I5: =TODAY() -> 45728 | M5: Fixed Scroll on #1, Digital Scroll on #2 | O5: 90 | Q5: 90° Street Elbow | R5: =1/0.4314 -> 2.3180343 | S5: lb/c.f. density of refrigerant vapor @ 55°F | V5: Air Tech Equipment Inc. | X5: RCS10G-121 | Y5: Nominal = 10 tons (CKT#1 = 1 - 10 ton compressor, two stage) | Z5: Staging = 0-100
A6: Circuit #: | C6: Identical Circuits (1=2) | O6: 100 | Q6: 45° Std Elbow | R6: =R2/(R5*60) -> 11.926382 | S6: CFM of refrigerant vapor, Suction | V6: Airetech Corp. | X6: RCS11F-125 | Y6: Nominal = 10 tons (CKT#1 = 2 - 5 ton compressors) | Z6: Staging = 0-50-100
O7: 110 | Q7: 45° Street Elbow | R7: =1/0.1114 -> 8.9766607 | S7: lb/c.f. density of saturated refrigerant vapor @ 125°F | V7: Allegheny Engineering Co. | X7: RCS12F-150 | Y7: Nominal = 12.5 tons (CKT#1 = 2 - 6.3 ton compressors) | Z7: Staging = 0-50-100 | AB7: 426725
A8: Refrigerant | D8: R-410A | O8: 120 | Q8: 180° Std Elbow | R8: =R7*(125+460.6)/(180+460.6) -> 8.2059514 | S8: lb/c.f. density of superheated refrigerant vapor @ 180°F | V8: Applied Air Engineering, Inc. | X8: RCS15F-180 | Y8: Nominal = 15 tons (CKT#1 = 2 - 7.5 ton compressors) | Z8: Staging = 0-50-100 | AB8: =AB7/2 -> 213362.5
A9: Circuit Cooling Capacity | D9: 17.8 | E9: TONS | F9: CKT#1 = 2 fixed speed compressors, CKT#2 = 2 fixed speed compressors | O9: 130 | Q9: Flow Through Branch | R9: =R2/(R8*60) -> 3.3689892 | S9: CFM of refrigerant vapor | V9: Briggs Equipment Sales | X9: RCS20F-240 | Y9: Nominal = 20 tons (CKT#1 = 2 - 10 ton compressors) | Z9: Staging = 0-50-100 | AB9: =AB8/12000 -> 17.780208
A10: Minimum Circuit Cooling Capacity | D10: =+D9/2 -> 8.9 | E10: TONS | F10: Staging = 0-25-50-75-100 | Q10: Straight-Through Flow No Reduction | V10: Brooks Air Systems, Inc. | X10: RCS015D | Y10: Nominal = 15 tons (CKT#1 = 1 - 7 ton compressor, CKT#2 = 1 - 7 ton compressor) | Z10: Staging = 0-50-100
A11: Condensing Temperature | D11: 120 | E11: oF | F11: Assumed | Q11: Straight-Through Flow Reduced 1/4 | S11: Type L | T11: Cross Section | V11: Carroll Air Systems, Inc. | X11: RCS016D | Y11: Nominal = 15 tons (CKT#1 = 1 - 7 ton compressor, CKT#2 = 1 - 7 ton compressor) | Z11: Staging = 0-50-100
A12: Saturated Suction Temperature (SST) | D12: 40 | E12: oF | F12: Enter Value between -60oF & 40oF | Q12: Straight-Through Flow Reduced 1/2 | R12: Pipe size O.D. | S12: I.D. | T12: (SF) | V12: CDI | X12: RCS020D | Y12: Nominal = 20 tons (CKT#1 = 1 - 10 ton compressor, CKT#2 = 2 - 4.5 ton compressors) | Z12: Staging = 0-25-50-75-100
A13: Superheat | D13: 10 | E13: oF | F13: Assumed | Q13: Globe or Solenoid Valve | R13: 0.5 | S13: 0.43 | T13: =(PI()*(S13^2)/4)/144 -> 0.0010084731 | V13: Climatec, Inc. | X13: RCS020D (Digital) | Y13: Nominal = 20 tons (CKT#1 = 1 - 10 ton Fixed Speed, CKT#2 = 1 - 10 ton Digital Scroll) | Z13: Modulating Control with Digital Compressor
A14: Discharge Refrigerant Temperature | D14: =IF(D11=80,140,IF(D11=100,160,IF(D11=120,180,190))) -> 180 | E14: oF | F14: Required if designing discharge line. | Q14: 60° Wye Valve | R14: 0.625 | S14: 0.545 | T14: =(PI()*(S14^2)/4)/144 -> 0.0016200201 | V14: Controls & Equipment | X14: RCS021D | Y14: Nominal = 20 tons (CKT#1 = 1 - 10 ton compressor, CKT#2 = 2 - 4.5 ton compressors) | Z14: Staging = 0-25-50-75-100
A15: (Circuit cooling capacity based off Refrigeration Effect from condenser tech data sheets) | Q15: 45° Wye Valve | R15: 0.75 | S15: 0.666 | T15: =(PI()*(S15^2)/4)/144 -> 0.0024192227 | V15: D & B Eng. of New Jersey, Inc. | X15: RCS025D | Y15: Nominal = 25 tons (CKT#1 = 1 - 11.5 ton compressor, CKT#2 = 2 - 5.5 ton compressors) | Z15: Staging = 0-25-50-75-100
C16: LIQUID LINE | Q16: Angle Valve | R16: 0.875 | S16: 0.785 | T16: =(PI()*(S16^2)/4)/144 -> 0.003360986 | V16: Daikin Applied Birmingham | X16: RCS025D (Digital) | Y16: Nominal = 25 tons (CKT#1 = 1 - 11.5 ton Fixed Speed, CKT#2 = 1 - 11.5 ton Digital Scroll)) | Z16: Modulating Control with Digital Compressor
Q17: Gate Valve | R17: 1.125 | S17: 1.025 | T17: =(PI()*(S17^2)/4)/144 -> 0.0057302705 | V17: Daikin Applied Atlanta | X17: RCS026D | Y17: Nominal = 25 tons (CKT#1 = 1 - 11.5 ton compressor, CKT#2 = 2 - 5.5 ton compressors) | Z17: Staging = 0-25-50-75-100
C18: Fitting/Valve Losses in Equivalent Feet of Pipe | H18: Table Data | Q18: Swing Check | R18: 1.375 | S18: 1.265 | T18: =(PI()*(S18^2)/4)/144 -> 0.0087278734 | V18: Daikin Applied New York | X18: RCS030D | Y18: Nominal = 30 tons (CKT#1 = 1 - 13 ton compressor, CKT#2 = 2 - 6 ton compressors) | Z18: Staging = 0-25-50-75-100
C19: Accessory | D19: Quantity | E19: Equivalent Losses | H19: Table Le | I19: ='R-410A_Data'!C25 -> 100 | J19: FEET | Q19: Sight Glass | R19: 1.625 | S19: 1.505 | T19: =(PI()*(S19^2)/4)/144 -> 0.012353795 | V19: Daikin Applied South Florida | X19: RCS030D (Digital) | Y19: Nominal = 30 tons (CKT#1 = 1 - 13 ton Fixed Speed, CKT#2 = 1-13 ton Digital Scroll) | Z19: Modulating Control with Digital Compressor
C20: 90° Std Elbow | D20: 8 | E20: ='R-410A_Equivalent_Length'!D30 -> 12 | F20: FEET | H20: Table Dt | I20: ='R-410A_Data'!C27 -> 1 | J20: oF | Q20: Filter Drier | R20: 2.125 | S20: 1.985 | T20: =(PI()*(S20^2)/4)/144 -> 0.021490594 | V20: Daikin Applied Latin America | X20: RCS031D | Y20: Nominal = 30 tons (CKT#1 = 1 - 13 ton compressor, CKT#2 = 2 - 6 ton compressors) | Z20: Staging = 0-25-50-75-100
C21: 45° Std Elbow | D21: 0 | E21: ='R-410A_Equivalent_Length'!D36 -> 0 | F21: FEET | H21: Table DP | I21: ='R-410A_Data'!K8 -> 4.75 | J21: PSI | Q21: Suction Filter | R21: 2.625 | S21: 2.465 | T21: =(PI()*(S21^2)/4)/144 -> 0.033140666 | V21: ElitAir, Inc. | X21: RCS035D | Y21: Nominal = 35 tons (CKT#1 = 2 - 7.5 ton compressors, CKT#2 = 2 - 7.5 ton compressors) | Z21: Staging = 0-25-50-75-100
C22: Globe or Solenoid Valve | D22: 1 | E22: ='R-410A_Equivalent_Length'!D42 -> 17.5 | F22: FEET | H22: Table Capacity | I22: ='R-410A_Data'!O9 -> 14.3 | J22: TONS | Q22: Other | R22: 3.125 | S22: 2.945 | T22: =(PI()*(S22^2)/4)/144 -> 0.047304013 | V22: Engineered Equipment, Inc. | X22: RCS040D | Y22: Nominal = 40 tons (CKT#1 = 2 - 8.5 ton compressors, CKT#2 = 2 - 8.5 ton compressors) | Z22: Staging = 0-25-50-75-100
C23: Sight Glass | D23: 1 | E23: ='R-410A_Equivalent_Length'!I30 -> 1.1 | F23: FEET | H23: Actual / Operating Conditions | R23: 3.625 | S23: 3.425 | T23: =(PI()*(S23^2)/4)/144 -> 0.063980634 | V23: Enviroair Industries Inc. | X23: RCS042D | Y23: Nominal = 40 tons (CKT#1 = 2 - 8.5 ton compressors, CKT#2 = 2 - 8.5 ton compressors) | Z23: Staging = 0-25-50-75-100
C24: Filter Drier | D24: 1 | E24: ='R-410A_Equivalent_Length'!I36 -> 13.5 | F24: FEET | H24: Actual Le | I24: =SUM(E27,E20:E25)+12 -> 116.1 | J24: FEET | R24: 4.125 | S24: 3.905 | T24: =(PI()*(S24^2)/4)/144 -> 0.083170529 | V24: Ewing/Kessler Mech Solutions | X24: RCS045D | Y24: Nominal = 40 tons (CKT#1 = 2 - 10 ton compressors, CKT#2 = 2 - 10 ton compressors) | Z24: Staging = 0-25-50-75-100
C25: Click here to select fitting. | D25: 0 | E25: ='R-410A_Equivalent_Length'!I42 -> 0 | F25: FEET | H25: Actual Dt | I25: =I20*(I24/I19)*(D9/I22)^1.8 -> 1.7218026 | J25: oF | R25: 5.125 | S25: 4.875 | T25: =(PI()*(S25^2)/4)/144 -> 0.12962138 | V25: Gardiner | X25: RCS050D | Y25: Nominal = 50 tons (CKT#1 = 2 - 11.5 ton compressors, CKT#2 = 2 - 11.5 ton compressors) | Z25: Staging = 0-25-50-75-100
H26: Actual DP | I26: =I21*(I25/I20) -> 8.1785623 | J26: PSI | R26: 6.125 | S26: 5.845 | T26: =(PI()*(S26^2)/4)/144 -> 0.18633585 | V26: Global Mechanical Sys. Ltd. | X26: RCS051D | Y26: Nominal = 50 tons (CKT#1 = 2 - 11.5 ton compressors, CKT#2 = 2 - 11.5 ton compressors) | Z26: Staging = 0-25-50-75-100
C27: Length of Straight Pipe | E27: 60 | F27: FEET | H27: Line Capacity | I27: =I22*((I19/I24)*(I25/I20))^0.55 -> 17.761072 | J27: TONS | R27: 8.125 | S27: 7.725 | T27: =(PI()*(S27^2)/4)/144 -> 0.32548004 | V27: Global Price Mechanical | X27: RCS060D | Y27: Nominal = 60 tons (CKT#1 = 2 - 13 ton compressors, CKT#2 = 2 - 13 ton compressors) | Z27: Staging = 0-25-50-75-100
C28: Velocity at Rated Circuit Capacity | D28: =IF(E28<100,"Too Low",IF(E28>330,"Too High","Acceptable")) -> Acceptable | E28: =R4*(D9/D10)/VLOOKUP(I28,$R$13:$T$27,3,FALSE) -> 319.60674 | F28: Feet/Min. | H28: Size of Liquid Line | I28: =IF(E27=0,"N/A",'R-410A_Data'!P9) -> 0.75 | J28: INCHES | V28: H.V.A.C. Sales, Ltd. | X28: RCS062D | Y28: Nominal = 60 tons (CKT#1 = 2 - 13 ton compressors, CKT#2 = 2 - 13 ton compressors) | Z28: Staging = 0-25-50-75-100
C29: Calculations Based on Ch. 1, 2014 ASHRAE Handbook REFRIGERATION | V29: Harrison Energy Partners | X29: RCS063D | Y29: Nominal = 60 tons (CKT#1 = 2 - 13 ton compressors, CKT#2 = 2 - 13 ton compressors) | Z29: Staging = 0-25-50-75-100
V30: Havtech | X30: RCS068D | Y30: Nominal = 70 tons (CKT#1 = 2 - 15 ton compressors, CKT#2 = 2 - 15 ton compressorss) | Z30: Staging = 0-25-50-75-100
C31: SUCTION LINE | V31: Heaven Engineering Co. | X31: RCS070D | Y31: Nominal = 70 tons (CKT#1 = 3 - 10 ton compressors, CKT#2 = 3 - 10 ton compressors) | Z31: Staging = 0-16-33-50-67-83-100
V32: Hoffman & Hoffman, Inc. | X32: RCS071D | Y32: Nominal = 70 tons (CKT#1 = 3 - 10 ton compressors, CKT#2 = 3 - 10 ton compressors) | Z32: Staging = 0-16-33-50-67-83-100
C33: Fitting/Valve Losses in Equivalent Feet of Pipe | H33: Table Data - Horizontal Pipe | V33: HTS New England | X33: RCS072D | Y33: Nominal = 70 tons (CKT#1 = 3 - 10 ton compressors, CKT#2 = 3 - 10 ton compressors) | Z33: Staging = 0-16-33-50-67-83-100
C34: Accessory | D34: Quantity | E34: Equivalent Losses | H34: Table Le | I34: ='R-410A_Data'!C25 -> 100 | J34: FEET | V34: HTS Engineering Ltd. | X34: RCS075D | Y34: Nominal = 75 tons (CKT#1 = 3 - 11.5 ton compressors, CKT#2 = 3 - 11.5 ton compressors) | Z34: Staging = 0-16-33-50-67-83-100
C35: 90° Std Elbow | D35: 8 | E35: ='R-410A_Equivalent_Length'!O30 -> 26.4 | F35: FEET | H35: Table Dt | I35: ='R-410A_Data'!C26 -> 2 | J35: oF | V35: I.T.C. Technologies | X35: RCS079D | Y35: Nominal = 80 tons (CKT#1 = 3 - 11.5 ton compressors, CKT#2 = 3 - 13 ton compressors) | Z35: Staging = 0-16-33-50-67-83-100
C36: 45° Std Elbow | D36: 0 | E36: ='R-410A_Equivalent_Length'!O36 -> 0 | F36: FEET | H36: Table DP | I36: ='R-410A_Data'!AK7 -> 4.5063 | J36: PSI | V36: Indiana Thermal Solutions | X36: RCS080D | Y36: Nominal = 80 tons (CKT#1 = 3 - 11.5 ton compressors, CKT#2 = 3 - 11.5 ton compressors) | Z36: Staging = 0-16-33-50-67-83-100
C37: Click here to select fitting. | D37: 0 | E37: ='R-410A_Equivalent_Length'!O42 -> 0 | F37: FEET | H37: Table Capacity | I37: ='R-410A_Data'!AP8 -> 13.74 | J37: TONS | V37: Kehoe Equipment Ltd. | X37: RCS081D | Y37: Nominal = 80 tons (CKT#1 = 3 - 11.5 ton compressors, CKT#2 = 3 - 11.5 ton compressors) | Z37: Staging = 0-16-33-50-67-83-100
C38: (Assumes ?? traps) | H38: Actual / Operating Conditions - Horizontal Pipe | V38: Long Building Tech | X38: RCS085D | Y38: Nominal = 85 tons (CKT#1 = 3 - 13 ton compressors, CKT#2 = 3 - 13 ton compressors) | Z38: Staging = 0-16-33-50-67-83-100
C39: Length of Horizontal Suction Pipe | E39: =E27-E45 -> 55 | F39: FEET | H39: Actual Le | I39: =SUM(E39,E35:E37)+12 -> 93.4 | J39: FEET | V39: M & M Engineering Limited | X39: RCS090D | Y39: Nominal = 90 tons (CKT#1 = 3 - 13 ton compressors, CKT#2 = 3 - 13 ton compressors) | Z39: Staging = 0-16-33-50-67-83-100
C40: Horizontal Suction @ Min CKT Capacity | D40: =IF(E40<500,"Too Low","Acceptable") -> Acceptable | E40: =R6/VLOOKUP(E52,$R$13:$T$27,3,FALSE) -> 1366.4705 | F40: Ft. / Min | H40: Actual Dt | I40: =I35*(I39/I34)*(D9/I37)^1.8 -> 2.9768487 | J40: oF | V40: Mason & Barry, Inc. | X40: RCS091D | Y40: Nominal = 90 tons (CKT#1 = 3 - 13 ton compressors, CKT#2 = 3 - 13 ton compressors) | Z40: Staging = 0-16-33-50-67-83-100
...

Sheet R-410A_Data
A1: 2006 ASHRAE Handbook Refrigeration | F1: Table Data | H1: Inputs | J1: Calculated Data | L1: Curve Fit Data
A3: Table 8 Suction, discharge, and Liquid Line Capacities in Tons for Refrigerant 410A | AN3: Determines Minimum Suction Line Size
A4: Line Size | B4: Suction Lines (Dt = 2oF) | G4: Discharge Lines (Dt = 1oF, Dp = 4.75 psi) | I4: Line Size | J4: Liquid Lines | M4: Determines Minimum Liquid Line Size | W4: Info Found Below Table 8 | AA4: Interpolation of Suction & Discharge Multipliers | AJ4: Table 8 - Curve Fit w/ Suction Multiplier | AN4: Suction Line Capacity | AO4: Look Up Sufficient Suction Line Capacity | AP4: Determine Minimum Suction Line Capacity | AQ4: Corresponding Suction Line Size, OD
B5: Saturated Suction Temperature, oF | J5: See notes a | M5: Look Up Sufficient Liquid Line Capacities | N5: Line Size | O5: Determine Minimum Liquid Line Capacity | P5: Corresponding Liquid Line Size, OD | R5: Suction Line Curve Fit | W5: Condensing Temperature | X5: Suction Line | Y5: Discharge Line | AA5: Act. Cond. Temp. | AB5: Min # for Interpolation | AC5: Max # for Interpolation | AD5: Known x's | AE5: Known y's Suction | AF5: Known y's Discharge | AG5: Suction Line | AH5: Discharge Line | AJ5: SST | AK5: Curve Fit | AL5: Suction Line Capacity | AM5: Type L Copper, OD
A6: Type L Copper, OD | B6: -40 | C6: -20 | D6: 0 | E6: 20 | F6: 40 | G6: Saturated Suction Temperature, oF | I6: Type L Copper, OD | J6: Vel = | K6: Dt = 1oF | N6: Type L Copper, OD | R6: SST | S6: Curve Fit | T6: =A6 -> Type L Copper, OD | U6: Suction Line Capacity | AJ6: oF | AK6: Dp (psi/100ft) | AN6: tons
B7: Corresponding Dp, psi/100ft | J7: fpm | K7: Dp (psi) = | R7: oF | S7: Dp (psi/100ft) | W7: oF | X7: multiplier | Y7: multiplier | AA7: oF | AG7: multiplier | AH7: multiplier | AJ7: =R8 -> 40 | AK7: =S8 -> 4.5063 | AL7: tons | AN7: ='R-410A_Calculator'!D9 -> 17.8
B8: 1.27 | C8: 1.85 | D8: 2.57 | E8: 3.46 | F8: 4.5 | G8: -40 | H8: 40 | J8: 100 | K8: 4.75 | R8: ='R-410A_Calculator'!D12 -> 40 | S8: =0.0002*R8^2 + 0.0403*R8 + 2.5743 -> 4.5063 | U8: tons | W8: 80 | X8: 1.17 | Y8: 0.815 | AA8: ='R-410A_Calculator'!D11 -> 120 | AB8: =IF($AA$8>=W8,W8,"") -> 80 | AC8: =IF($AA$8<=W8,W8,"") | AD8: =MAX(AB8:AB13) -> 120 | AE8: =VLOOKUP(AD8,W8:Y13,2) -> 0.889 | AF8: =VLOOKUP(AD8,W8:Y13,3) -> 1.096 | AG8: =IF(AA8=80,X8,IF(AA8=90,X9,IF(AA8=100,X10,IF(AA8=110,X11,IF(AA8=120,X12,IF(AA8=130,X13,FORECAST(AA8,AE8:AE9,AD8:AD9))))))) -> 0.889 | AH8: =IF(AA8=80,Y8,IF(AA8=90,Y9,IF(AA8=100,Y10,IF(AA8=110,Y11,IF(AA8=120,Y12,IF(AA8=130,Y13,FORECAST(AA8,AF8:AF9,AD8:AD9))))))) -> 1.096 | AL8: =$AG$8*U9 -> 0.7879207 | AM8: =A9 -> 0.5 | AO8: =IF(AL8>=$AN$7,AL8,"") | AP8: =MIN(AO8:AO22) -> 13.74 | AQ8: =VLOOKUP(AP8,AL8:AM22,2) -> 1.375
A9: 0.5 | B9: 0.17 | C9: 0.27 | D9: 0.42 | E9: 0.62 | F9: 0.89 | G9: 1.17 | H9: 1.33 | I9: =A9 -> 0.5 | J9: 2 | K9: 4.6 | M9: =IF(K9>='R-410A_Calculator'!$D$9,'R-410A_Data'!K9,"") | N9: =A9 -> 0.5 | O9: =MIN(M9:M20) -> 14.3 | P9: =VLOOKUP(O9,K9:N20,4) -> 0.75 | T9: =A9 -> 0.5 | U9: =0.00007*R8^2 + 0.0089*R8 + 0.4183 -> 0.8863 | W9: 90 | X9: 1.104 | Y9: 0.889 | AB9: =IF($AA$8>=W9,W9,"") -> 90 | AC9: =IF($AA$8<=W9,W9,"") | AD9: =MIN(AC8:AC13) -> 120 | AE9: =VLOOKUP(AD9,W8:Y13,2) -> 0.889 | AF9: =VLOOKUP(AD9,W8:Y13,3) -> 1.096 | AL9: =$AG$8*U10 -> 1.445514 | AM9: =A10 -> 0.625 | AO9: =IF(AL9>=$AN$7,AL9,"")
A10: 0.625 | B10: 0.31 | C10: 0.51 | D10: 0.79 | E10: 1.17 | F10: 1.67 | G10: 2.2 | H10: 2.49 | I10: =A10 -> 0.625 | J10: 3.2 | K10: 8.6 | M10: =IF(K10>='R-410A_Calculator'!$D$9,'R-410A_Data'!K10,"") | N10: =A10 -> 0.625 | T10: =A10 -> 0.625 | U10: =0.0001*R8^2 + 0.0169*R8 + 0.79 -> 1.626 | W10: 100 | X10: 1.035 | Y10: 0.963 | AB10: =IF($AA$8>=W10,W10,"") -> 100 | AC10: =IF($AA$8<=W10,W10,"") | AL10: =$AG$8*U11 -> 2.5060021 | AM10: =A11 -> 0.75 | AO10: =IF(AL10>=$AN$7,AL10,"")
A11: 0.75 | B11: 0.53 | C11: 0.87 | D11: 1.35 | E11: 2 | F11: 2.84 | G11: 3.74 | H11: 4.23 | I11: =A11 -> 0.75 | J11: 1.7 | K11: 14.3 | M11: 14.3 | N11: =A11 -> 0.75 | T11: =A11 -> 0.75 | U11: =0.0002*R8^2 + 0.0287*R8 + 1.3509 -> 2.8189 | W11: 110 | X11: 0.964 | Y11: 1.032 | AB11: =IF($AA$8>=W11,W11,"") -> 110 | AC11: =IF($AA$8<=W11,W11,"") | AL11: =$AG$8*U12 -> 3.8491033 | AM11: =A12 -> 0.875 | AO11: =IF(AL11>=$AN$7,AL11,"")
A12: 0.875 | B12: 0.83 | C12: 1.35 | D12: 2.08 | E12: 3.08 | F12: 4.39 | G12: 5.76 | H12: 6.52 | I12: =A12 -> 0.875 | J12: 6.7 | K12: 22.6 | M12: =IF(K12>='R-410A_Calculator'!$D$9,'R-410A_Data'!K12,"") -> 22.6 | N12: =A12 -> 0.875 | T12: =A12 -> 0.875 | U12: =0.0003*R8^2 + 0.0442*R8 + 2.0817 -> 4.3297 | W12: 120 | X12: 0.889 | Y12: 1.096 | AB12: =IF($AA$8>=W12,W12,"") -> 120 | AC12: =IF($AA$8<=W12,W12,"") -> 120 | AL12: =$AG$8*U13 -> 7.9164561 | AM12: =A13 -> 1.125 | AO12: =IF(AL12>=$AN$7,AL12,"")
A13: 1.125 | B13: 1.69 | C13: 2.74 | D13: 4.22 | E13: 6.23 | F13: 8.86 | G13: 11.64 | H13: 13.17 | I13: =A13 -> 1.125 | J13: 11.4 | K13: 45.8 | M13: =IF(K13>='R-410A_Calculator'!$D$9,'R-410A_Data'!K13,"") -> 45.8 | N13: =A13 -> 1.125 | T13: =A13 -> 1.125 | U13: =0.0007*R8^2 + 0.0891*R8 + 4.2209 -> 8.9049 | W13: 130 | X13: 0.808 | Y13: 1.16 | AB13: =IF($AA$8>=W13,W13,"") | AC13: =IF($AA$8<=W13,W13,"") -> 130 | AL13: =$AG$8*U14 -> 13.736828 | AM13: =A14 -> 1.375 | AO13: 13.74
A14: 1.375 | B14: 2.95 | C14: 4.78 | D14: 7.34 | E14: 10.82 | F14: 15.41 | G14: 20.21 | H14: 22.88 | I14: =A14 -> 1.375 | J14: 17.4 | K14: 79.7 | M14: =IF(K14>='R-410A_Calculator'!$D$9,'R-410A_Data'!K14,"") -> 79.7 | N14: =A14 -> 1.375 | T14: =A14 -> 1.375 | U14: =0.0012*R8^2 + 0.1548*R8 + 7.34 -> 15.452 | AL14: =$AG$8*U15 -> 21.572474 | AM14: =A15 -> 1.625 | AO14: =IF(AL14>=$AN$7,AL14,"") -> 21.572474
A15: 1.625 | B15: 4.67 | C15: 7.56 | D15: 11.61 | E15: 17.14 | F15: 24.28 | G15: 31.92 | H15: 36.14 | I15: =A15 -> 1.625 | J15: 24.6 | K15: 125.9 | M15: =IF(K15>='R-410A_Calculator'!$D$9,'R-410A_Data'!K15,"") -> 125.9 | N15: =A15 -> 1.625 | T15: =A15 -> 1.625 | U15: =0.0018*R8^2 + 0.244*R8 + 11.626 -> 24.266 | AL15: =$AG$8*U16 -> 44.581572 | AM15: =A16 -> 2.125 | AO15: =IF(AL15>=$AN$7,AL15,"") -> 44.581572
A16: 2.125 | B16: 9.71 | C16: 15.71 | D16: 24.05 | E16: 35.45 | F16: 50.19 | G16: 65.88 | H16: 75.57 | I16: =A16 -> 2.125 | J16: 42.8 | K16: 260.7 | M16: =IF(K16>='R-410A_Calculator'!$D$9,'R-410A_Data'!K16,"") -> 260.7 | N16: =A16 -> 2.125 | T16: =A16 -> 2.125 | U16: =0.0037*R8^2 + 0.5035*R8 + 24.088 -> 50.148 | AL16: =$AG$8*U17 -> 78.424913 | AM16: =A17 -> 2.625 | AO16: =IF(AL16>=$AN$7,AL16,"") -> 78.424913
A17: 2.625 | B17: 17.17 | C17: 27.74 | D17: 42.45 | E17: 62.53 | F17: 88.43 | G17: 115.9 | H17: 131.2 | I17: =A17 -> 2.625 | J17: 66 | K17: 459.7 | M17: =IF(K17>='R-410A_Calculator'!$D$9,'R-410A_Data'!K17,"") -> 459.7 | N17: =A17 -> 2.625 | T17: =A17 -> 2.625 | U17: =0.0064*R8^2 + 0.8865*R8 + 42.517 -> 88.217 | AL17: =$AG$8*U18 -> 124.9205 | AM17: =A18 -> 3.125 | AO17: =IF(AL17>=$AN$7,AL17,"") -> 124.9205
A18: 3.125 | B18: 27.44 | C18: 44.24 | D18: 67.77 | E18: 99.53 | F18: 140.83 | G18: 184.62 | H18: 208.98 | I18: =A18 -> 3.125 | J18: 94.2 | K18: 733 | M18: =IF(K18>='R-410A_Calculator'!$D$9,'R-410A_Data'!K18,"") -> 733 | N18: =A18 -> 3.125 | T18: =A18 -> 3.125 | U18: =0.0102*R8^2 + 1.4103*R8 + 67.786 -> 140.518 | AL18: =$AG$8*U19 -> 185.15381 | AM18: =A19 -> 3.625 | AO18: =IF(AL18>=$AN$7,AL18,"") -> 185.15381
A19: 3.625 | B19: 40.84 | C19: 65.81 | D19: 100.5 | E19: 147.66 | F19: 208.65 | G19: 273.54 | H19: 309.64 | I19: =A19 -> 3.625 | J19: 127.4 | K19: 1087.5 | M19: =IF(K19>='R-410A_Calculator'!$D$9,'R-410A_Data'!K19,"") -> 1087.5 | N19: =A19 -> 3.625 | T19: =A19 -> 3.625 | U19: =0.0151*R8^2 + 2.0873*R8 + 100.62 -> 208.272 | AL19: =$AG$8*U20 -> 260.75259 | AM19: =A20 -> 4.125 | AO19: =IF(AL19>=$AN$7,AL19,"") -> 260.75259
A20: 4.125 | B20: 57.58 | C20: 92.66 | D20: 141.61 | E20: 208.22 | F20: 293.7 | G20: 385.08 | H20: 435.9 | I20: =A20 -> 4.125 | J20: 165.7 | K20: 1530.2 | M20: =IF(K20>='R-410A_Calculator'!$D$9,'R-410A_Data'!K20,"") -> 1530.2 | N20: =A20 -> 4.125 | T20: =A20 -> 4.125 | U20: =0.0212*R8^2 + 2.939*R8 + 141.83 -> 293.31 | AL20: =$AG$8*U21 -> 464.3087 | AM20: =A21 -> 5.125 | AO20: =IF(AL20>=$AN$7,AL20,"") -> 464.3087
A21: 5.125 | B21: 103.03 | C21: 165.73 | D21: 253.05 | E21: 370.82 | F21: 523.21 | G21: 686.18 | H21: 776.72 | I21: =A21 -> 5.125 | J21: 258.2 | K21: 2729.8 | M21: =IF(K21>='R-410A_Calculator'!$D$9,'R-410A_Data'!K21,"") -> 2729.8 | N21: =A21 -> 5.125 | T21: =A21 -> 5.125 | U21: =0.0375*R8^2 + 5.2273*R8 + 253.19 -> 522.282 | AL21: =$AG$8*U22 -> 745.23803 | AM21: =A22 -> 6.125 | AO21: =IF(AL21>=$AN$7,AL21,"") -> 745.23803
A22: 6.125 | B22: 166 | C22: 266.14 | D22: 405.75 | E22: 594.85 | F22: 839.82 | G22: 1099.1 | H22: 1244.13 | I22: =A22 -> 6.125 | J22: 371.1 | K22: 4383.7 | M22: =IF(K22>='R-410A_Calculator'!$D$9,'R-410A_Data'!K22,"") -> 4383.7 | N22: =A22 -> 6.125 | T22: =A22 -> 6.125 | U22: =0.0606*R8^2 + 8.3817*R8 + 406.06 -> 838.288 | AL22: =$AG$8*U23 -> 1537.8811 | AM22: =A23 -> 8.125 | AO22: =IF(AL22>=$AN$7,AL22,"") -> 1537.8811
A23: 8.125 | B23: 344.31 | C23: 551.73 | D23: 840.04 | E23: 1229.69 | F23: 1733.02 | G23: 2268.62 | H23: 2567.98 | I23: =A23 -> 8.125 | J23: 648.3 | K23: 9049.5 | M23: =IF(K23>='R-410A_Calculator'!$D$9,'R-410A_Data'!K23,"") -> 9049.5 | N23: =A23 -> 8.125 | T23: =A23 -> 8.125 | U23: =0.1238*R8^2 + 17.277*R8 + 840.74 -> 1729.9
A25: Table is based on | C25: 100 | D25: feet of equivalent length, Le. | W25: Portion of Table 8
A26: Suction Line Table Dt | C26: 2 | D26: oF | W26: Discharge Lines (Dt = 1oF, Dp = 3.05 psi) | Z26: Discharge Line Curve Fit | AB26: Curve Fit w/mulitplier | AD26: Determines Minimum Discharge Line Size | AI26: Determines Minimum HGBP Line Size
A27: Liquid Line Table Dt | C27: 1 | D27: oF | AD27: Discharge Line Capacity | AE27: Look Up Sufficient Discharge Line Capacity | AF27: Determine Minimum Discharge Line Capacity | AG27: Corresponding Discharge Line Size, OD | AI27: HGBP Line Capacity | AJ27: Look Up Sufficient HGBP Line Capacity | AK27: Determine Minimum HGBP Line Capacity | AL27: Corresponding HGBP Line Size, OD
A28: Discharge Line Table Dt | C28: 1 | D28: oF | W28: Saturated Suction Temperature, oF | Y28: SST | Z28: Discharge Line Capacity | AB28: Discharge Line Capacity | AC28: Type L Copper, OD
A29: Discharge Line Table Dp | C29: 4.75 | D29: PSI | Y29: oF | AD29: tons | AI29: tons
W30: -40 | X30: 40 | Y30: ='R-410A_Calculator'!D12 -> 40 | Z30: tons | AB30: tons | AD30: ='R-410A_Calculator'!D9 -> 17.8 | AI30: ='R-410A_Calculator'!E62/3 -> 1.4833333
W31: =G9 -> 1.17 | X31: =H9 -> 1.33 | Z31: =0.002*Y30 + 1.25 -> 1.33 | AB31: =$AH$8*Z31 -> 1.45768 | AC31: =A9 -> 0.5 | AE31: =IF(AB31>=$AD$30,AB31,"") | AF31: =MIN(AE31:AE44) -> 25.077576 | AG31: =VLOOKUP(AF31,AB31:AC44,2) -> 1.375 | AJ31: =IF(AB31>=$AI$30,AB31,"") | AK31: =MIN(AJ31:AJ40) -> 2.727944 | AL31: =VLOOKUP(AK31,AB31:AC44,2) -> 0.625
W32: =G10 -> 2.2 | X32: =H10 -> 2.49 | Z32: =0.0036*Y30 + 2.345 -> 2.489 | AB32: =$AH$8*Z32 -> 2.727944 | AC32: =A10 -> 0.625 | AE32: =IF(AB32>=$AD$30,AB32,"") | AJ32: =IF(AB32>=$AI$30,AB32,"") -> 2.727944
W33: =G11 -> 3.74 | X33: =H11 -> 4.23 | Z33: =0.0061*Y30 + 3.985 -> 4.229 | AB33: =$AH$8*Z33 -> 4.634984 | AC33: =A11 -> 0.75 | AE33: =IF(AB33>=$AD$30,AB33,"") | AJ33: =IF(AB33>=$AI$30,AB33,"") -> 4.634984
W34: =G12 -> 5.76 | X34: =H12 -> 6.52 | Z34: =0.0095*Y30 + 6.14 -> 6.52 | AB34: =$AH$8*Z34 -> 7.14592 | AC34: =A12 -> 0.875 | AE34: =IF(AB34>=$AD$30,AB34,"") | AJ34: =IF(AB34>=$AI$30,AB34,"") -> 7.14592
A35: Type L Copper | W35: =G13 -> 11.64 | X35: =H13 -> 13.17 | Z35: =0.0191*Y30 + 12.405 -> 13.169 | AB35: =$AH$8*Z35 -> 14.433224 | AC35: =A13 -> 1.125 | AE35: =IF(AB35>=$AD$30,AB35,"") | AJ35: =IF(AB35>=$AI$30,AB35,"") -> 14.433224
A36: OD | B36: ID | C36: Sq. Ft. | W36: =G14 -> 20.21 | X36: =H14 -> 22.88 | Z36: =0.0334*Y30 + 21.545 -> 22.881 | AB36: =$AH$8*Z36 -> 25.077576 | AC36: =A14 -> 1.375 | AE36: =IF(AB36>=$AD$30,AB36,"") -> 25.077576 | AJ36: =IF(AB36>=$AI$30,AB36,"") -> 25.077576
A37: 0.5 | B37: 0.43 | C37: =(B37/2)^2*PI()/144 -> 0.0010084731 | W37: =G15 -> 31.92 | X37: =H15 -> 36.14 | Z37: =0.0527*Y30 + 34.03 -> 36.138 | AB37: =$AH$8*Z37 -> 39.607248 | AC37: =A15 -> 1.625 | AE37: =IF(AB37>=$AD$30,AB37,"") -> 39.607248 | AJ37: =IF(AB37>=$AI$30,AB37,"") -> 39.607248
A38: 0.625 | B38: 0.545 | C38: =(B38/2)^2*PI()/144 -> 0.0016200201 | W38: =G16 -> 65.88 | X38: =H16 -> 75.57 | Z38: =0.1211*Y30 + 70.725 -> 75.569 | AB38: =$AH$8*Z38 -> 82.823624 | AC38: =A16 -> 2.125 | AE38: =IF(AB38>=$AD$30,AB38,"") -> 82.823624 | AJ38: =IF(AB38>=$AI$30,AB38,"") -> 82.823624
A39: 0.75 | B39: 0.666 | C39: =(B39/2)^2*PI()/144 -> 0.0024192227 | W39: =G17 -> 115.9 | X39: =H17 -> 131.2 | Z39: =0.1913*Y30 + 123.55 -> 131.202 | AB39: =$AH$8*Z39 -> 143.79739 | AC39: =A17 -> 2.625 | AE39: =IF(AB39>=$AD$30,AB39,"") -> 143.79739 | AJ39: =IF(AB39>=$AI$30,AB39,"") -> 143.79739
A40: 0.875 | B40: 0.785 | C40: =(B40/2)^2*PI()/144 -> 0.003360986 | W40: =G18 -> 184.62 | X40: =H18 -> 208.98 | Z40: =0.3045*Y30 + 196.8 -> 208.98 | AB40: =$AH$8*Z40 -> 229.04208 | AC40: =A18 -> 3.125 | AE40: =IF(AB40>=$AD$30,AB40,"") -> 229.04208 | AJ40: =IF(AB40>=$AI$30,AB40,"") -> 229.04208
A41: 1.125 | B41: 1.025 | C41: =(B41/2)^2*PI()/144 -> 0.0057302705 | W41: =G19 -> 273.54 | X41: =H19 -> 309.64 | Z41: =0.4512*Y30 + 291.59 -> 309.638 | AB41: =$AH$8*Z41 -> 339.36325 | AC41: =A19 -> 3.625 | AE41: =IF(AB41>=$AD$30,AB41,"") -> 339.36325 | AJ41: =IF(AB41>=$AI$30,AB41,"") -> 339.36325
A42: 1.375 | B42: 1.265 | C42: =(B42/2)^2*PI()/144 -> 0.0087278734 | W42: =G20 -> 385.08 | X42: =H20 -> 435.9 | Z42: =0.6353*Y30 + 410.49 -> 435.902 | AB42: =$AH$8*Z42 -> 477.74859 | AC42: =A20 -> 4.125 | AE42: =IF(AB42>=$AD$30,AB42,"") -> 477.74859 | AJ42: =IF(AB42>=$AI$30,AB42,"") -> 477.74859
...

Sheet R-410A_Equivalent_Length
A1: Fitting Losses in Equivalent Feet of Pipe (Table 16 2006 ASHRAE REFRIGERATION & Table 4 McQuay AG31-011)
B2: Smooth Bend Elbows | H2: Smooth Bend Tee | L2: Valve Losses in Equivalent Feet of Pipe (Table 18 2006 ASHRAE REFRIGERATION, Table 5 McQuay AG31-011)
A3: Click here to select fitting. | B3: 90° Std Elbow | C3: 90° Long Radius Elbow | D3: 90° Street Elbow | E3: 45° Std Elbow | F3: 45° Street Elbow | G3: 180° Std Elbow | H3: Flow Through Branch | I3: Straight-Through Flow No Reduction | J3: Straight-Through Flow Reduced 1/4 | K3: Straight-Through Flow Reduced 1/2 | L3: Globe or Solenoid Valve | M3: 60° Wye Valve | N3: 45° Wye Valve | O3: Angle Valve | P3: Gate Valve | Q3: Swing Check | R3: Sight Glass | S3: Filter Drier | T3: Suction Filter | U3: Other
A4: 0.5 | B4: 1.4 | C4: 0.9 | D4: 2.3 | E4: 0.7 | F4: 1.1 | G4: 2.3 | H4: 2.7 | I4: 0.9 | J4: 1.2 | K4: 1.4 | L4: 17 | M4: 8 | N4: 6 | O4: 6 | P4: 0.6 | Q4: 5 | R4: 1 | S4: 12 | T4: 15 | U4: -1
A5: 0.75 | B5: =(B6-B4)/2+B4 -> 1.5 | C5: =(C6-C4)/2+C4 -> 0.95 | D5: =(D6-D4)/2+D4 -> 2.4 | E5: =(E6-E4)/2+E4 -> 0.75 | F5: =(F6-F4)/2+F4 -> 1.2 | G5: =(G6-G4)/2+G4 -> 2.4 | H5: =(H6-H4)/2+H4 -> 2.85 | I5: =(I6-I4)/2+I4 -> 0.95 | ... T5: =(T6-T4)/2+T4 -> 16 | U5: -1
A6: 0.625 | B6: 1.6 | C6: 1 | D6: 2.5 | E6: 0.8 | F6: 1.3 | G6: 2.5 | H6: 3 | I6: 1 | J6: 1.4 | K6: 1.6 | L6: 18 | M6: 9 | N6: 7 | O6: 7 | P6: 0.7 | Q6: 6 | R6: 1.2 | S6: 15 | T6: 17 | U6: -1
A7: 0.875 | B7: 2 | C7: 1.4 | D7: 3.2 | E7: 0.9 | F7: 1.6 | G7: 3.2 | H7: 4 | I7: 1.4 | J7: 1.9 | K7: 2 | L7: 22 | M7: 11 | N7: 9 | O7: 9 | P7: 0.9 | Q7: 8 | R7: 1.6 | S7: 21 | T7: 22 | U7: -1
A8: 1.125 | B8: 2.6 | C8: 1.7 | D8: 4.1 | E8: 1.3 | F8: 2.1 | G8: 4.1 | H8: 5 | I8: 1.7 | J8: 2.2 | K8: 2.6 | L8: 29 | M8: 15 | N8: 12 | O8: 12 | P8: 1 | Q8: 10 | R8: 2 | S8: 26 | T8: 25 | U8: -1
A9: 1.375 | B9: 3.3 | C9: 2.3 | D9: 5.6 | E9: 1.7 | F9: 3 | G9: 5.6 | H9: 7 | I9: 2.3 | J9: 3.1 | K9: 3.3 | L9: 38 | M9: 20 | N9: 15 | O9: 15 | P9: 1.5 | Q9: 14 | R9: 2.5 | S9: 35 | T9: 36 | U9: -1
A10: 1.625 | B10: 4 | C10: 2.6 | D10: 6.3 | E10: 2.1 | F10: 3.4 | G10: 6.3 | H10: 8 | I10: 2.6 | J10: 3.7 | K10: 4 | L10: 43 | M10: 24 | N10: 18 | O10: 18 | P10: 1.8 | Q10: 16 | R10: 2.6 | S10: -1 | T10: 40 | U10: -1
A11: 2.125 | B11: 5 | C11: 3.3 | D11: 8.2 | E11: 2.6 | F11: 4.5 | G11: 8.2 | H11: 10 | I11: 3.3 | J11: 4.7 | K11: 5 | L11: 55 | M11: 30 | N11: 24 | O11: 24 | P11: 2.3 | Q11: 20 | R11: -1 | S11: -1 | T11: -1 | U11: -1
A12: 2.625 | B12: 6 | C12: 4.1 | D12: 10 | E12: 3.2 | F12: 5.2 | G12: 10 | H12: 12 | I12: 4.1 | J12: 5.6 | K12: 6 | L12: 69 | M12: 35 | N12: 29 | O12: 29 | P12: 2.8 | Q12: 25 | R12: -1 | S12: -1 | T12: -1 | U12: -1
A13: 3.125 | B13: 7.5 | C13: 5 | D13: 12 | E13: 4 | F13: 6.4 | G13: 12 | H13: 15 | I13: 5 | J13: 7 | K13: 7.5 | L13: 84 | M13: 43 | N13: 35 | O13: 35 | P13: 3.2 | Q13: 30 | R13: -1 | S13: -1 | T13: -1 | U13: -1
A14: 3.625 | B14: 9 | C14: 5.9 | D14: 15 | E14: 4.7 | F14: 7.3 | G14: 15 | H14: 18 | I14: 5.9 | J14: 8 | K14: 9 | L14: 100 | M14: 50 | N14: 41 | O14: 41 | P14: 4 | Q14: 35 | R14: -1 | S14: -1 | T14: -1 | U14: -1
A15: 4.125 | B15: 10 | C15: 6.7 | D15: 17 | E15: 5.2 | F15: 8.5 | G15: 17 | H15: 21 | I15: 6.7 | J15: 9 | K15: 10 | L15: 120 | M15: 58 | N15: 47 | O15: 47 | P15: 4.5 | Q15: 40 | R15: -1 | S15: -1 | T15: -1 | U15: -1
A16: 5.125 | B16: 13 | C16: 8.2 | D16: 21 | E16: 6.5 | F16: 11 | G16: 21 | H16: 25 | I16: 8.2 | J16: 12 | K16: 13 | L16: 140 | M16: 71 | N16: 58 | O16: 58 | P16: 6 | Q16: 50 | R16: -1 | S16: -1 | T16: -1 | U16: -1
A17: 6.125 | B17: 16 | C17: 10 | D17: 25 | E17: 7.9 | F17: 13 | G17: 25 | H17: 30 | I17: 10 | J17: 14 | K17: 16 | L17: 170 | M17: 88 | N17: 70 | O17: 70 | P17: 7 | Q17: 60 | R17: -1 | S17: -1 | T17: -1 | U17: -1
A18: 8.125 | B18: 20 | C18: 13 | D18: -1 | E18: 10 | F18: -1 | G18: 33 | H18: 40 | I18: 13 | J18: 18 | K18: 20 | L18: 220 | M18: 115 | N18: 85 | O18: 85 | P18: 9 | Q18: 80 | R18: -1 | S18: -1 | T18: -1 | U18: -1
B19: 2 | C19: 3 | D19: 4 | E19: 5 | F19: 6 | G19: 7 | H19: 8 | I19: 9 | J19: 10 | K19: 11 | L19: 12 | M19: 13 | N19: 14 | O19: 15 | P19: 16 | Q19: 17 | R19: 18 | S19: 19 | T19: 20 | U19: 21
A20: Notes:
B21: Value of -1 in the table represents No data, and prompts the user to enter a value.
B22: In order to search the entire table, the IF() statement needed to be written 4 times (1st - 4th Attempt) due to the limits of the IF() statement in Excel for the Liquid & Suction line componenets below.
A24: Liquid Line Components | L24: Suction Line Components | R24: Discharge Line Components | X24: HGBP Line Components
A25: Liquid Line Size | B25: ='R-410A_Data'!P9 -> 0.75 | L25: Suction Line Size | M25: ='R-410A_Data'!AQ8 -> 1.375 | R25: Discharge Line Size | S25: ='R-410A_Data'!AG31 -> 1.375 | X25: HGBP Line Size | Y25: ='R-410A_Data'!AL31 -> 0.625
A27: 1st Component | F27: 4th Component | L27: 1st Component | R27: 1st Component | X27: 1st Component
A28: ='R-410A_Calculator'!C20 -> 90° Std Elbow | B28: =IF(A28="Click here to select fitting.",0,IF(A28="90° Std Elbow",VLOOKUP($B$25,$A$4:$U$18,2),IF(A28="90° Long Radius Elbow",VLOOKUP($B$25,$A$4:$U$18,3),IF(A28="90° Street Elbow",VLOOKUP($B$25,$A$4:$U$18,4),"FALSE")))) -> 1.5 | C28: 1st Attempt | D28: =IF(MAX(B28:B31)<0,"Enter Value",MAX(B28:B31)) -> 1.5 | E28: FT | F28: ='R-410A_Calculator'!C23 -> Sight Glass | G28: =IF(F28="Click here to select fitting.",0,IF(F28="90° Std Elbow",VLOOKUP($B$25,$A$4:$U$18,2),IF(F28="90° Long Radius Elbow",VLOOKUP($B$25,$A$4:$U$18,3),IF(F28="90° Street Elbow",VLOOKUP($B$25,$A$4:$U$18,4),"FALSE")))) -> FALSE | H28: 1st Attempt | I28: =IF(MAX(G28:G31)<0,"Enter Value",MAX(G28:G31)) -> 1.1 | J28: FT | L28: ='R-410A_Calculator'!C35 -> 90° Std Elbow | M28: =IF(L28="Click here to select fitting.",0,IF(L28="90° Std Elbow",VLOOKUP($M$25,$A$4:$U$18,2),IF(L28="90° Long Radius Elbow",VLOOKUP($M$25,$A$4:$U$18,3),IF(L28="90° Street Elbow",VLOOKUP($M$25,$A$4:$U$18,4),"FALSE")))) -> 3.3 | N28: 1st Attempt | O28: =IF(MAX(M28:M31)<0,"Enter Value",MAX(M28:M31)) -> 3.3 | P28: FT | R28: ='R-410A_Calculator'!C77 -> 90° Std Elbow | S28: =IF(R28="Click here to select fitting.",0,IF(R28="90° Std Elbow",VLOOKUP($S$25,$A$4:$U$18,2),IF(R28="90° Long Radius Elbow",VLOOKUP($S$25,$A$4:$U$18,3),IF(R28="90° Street Elbow",VLOOKUP($S$25,$A$4:$U$18,4),"FALSE")))) -> 3.3 | T28: 1st Attempt | U28: =IF(MAX(S28:S31)<0,"Enter Value",MAX(S28:S31)) -> 3.3 | V28: FT | X28: ='R-410A_Calculator'!C67 -> 90° Std Elbow | Y28: =IF(X28="Click here to select fitting.",0,IF(X28="90° Std Elbow",VLOOKUP($Y$25,$A$4:$U$18,2),IF(X28="90° Long Radius Elbow",VLOOKUP($Y$25,$A$4:$U$18,3),IF(X28="90° Street Elbow",VLOOKUP($Y$25,$A$4:$U$18,4),"FALSE")))) -> 1.4 | Z28: 1st Attempt | AA28: =IF(MAX(Y28:Y31)<0,"Enter Value",MAX(Y28:Y31)) -> 1.4 | AB28: FT
B29: =IF(B28="FALSE",IF(A28="45° Std Elbow",VLOOKUP($B$25,$A$4:$U$18,5),IF(A28="45° Street Elbow",VLOOKUP($B$25,$A$4:$U$18,6),IF(A28="180° Std Elbow",VLOOKUP($B$25,$A$4:$U$18,7),IF(A28="Flow Through Branch",VLOOKUP($B$25,$A$4:$U$18,8),IF(A28="Straight-Through Flow No Reduction",VLOOKUP($B$25,$A$4:$U$18,9),IF(A28="Straight-Through Flow Reduced 1/4",VLOOKUP($B$25,$A$4:$U$18,10),"FALSE"))))))) -> FALSE | C29: 2nd Attempt | D29: ='R-410A_Calculator'!D20 -> 8 | E29: QTY | G29: =IF(G28="FALSE",IF(F28="45° Std Elbow",VLOOKUP($B$25,$A$4:$U$18,5),IF(F28="45° Street Elbow",VLOOKUP($B$25,$A$4:$U$18,6),IF(F28="180° Std Elbow",VLOOKUP($B$25,$A$4:$U$18,7),IF(F28="Flow Through Branch",VLOOKUP($B$25,$A$4:$U$18,8),IF(F28="Straight-Through Flow No Reduction",VLOOKUP($B$25,$A$4:$U$18,9),IF(F28="Straight-Through Flow Reduced 1/4",VLOOKUP($B$25,$A$4:$U$18,10),"FALSE"))))))) -> FALSE | H29: 2nd Attempt | I29: ='R-410A_Calculator'!D23 -> 1 | J29: QTY | M29: =IF(M28="FALSE",IF(L28="45° Std Elbow",VLOOKUP($M$25,$A$4:$U$18,5),IF(L28="45° Street Elbow",VLOOKUP($M$25,$A$4:$U$18,6),IF(L28="180° Std Elbow",VLOOKUP($M$25,$A$4:$U$18,7),IF(L28="Flow Through Branch",VLOOKUP($M$25,$A$4:$U$18,8),IF(L28="Straight-Through Flow No Reduction",VLOOKUP($M$25,$A$4:$U$18,9),IF(L28="Straight-Through Flow Reduced 1/4",VLOOKUP($M$25,$A$4:$U$18,10),"FALSE"))))))) -> FALSE | N29: 2nd Attempt | O29: ='R-410A_Calculator'!D35 -> 8 | P29: QTY | S29: =IF(S28="FALSE",IF(R28="45° Std Elbow",VLOOKUP($S$25,$A$4:$U$18,5),IF(R28="45° Street Elbow",VLOOKUP($S$25,$A$4:$U$18,6),IF(R28="180° Std Elbow",VLOOKUP($S$25,$A$4:$U$18,7),IF(R28="Flow Through Branch",VLOOKUP($S$25,$A$4:$U$18,8),IF(R28="Straight-Through Flow No Reduction",VLOOKUP($S$25,$A$4:$U$18,9),IF(R28="Straight-Through Flow Reduced 1/4",VLOOKUP($S$25,$A$4:$U$18,10),"FALSE"))))))) -> FALSE | T29: 2nd Attempt | U29: ='R-410A_Calculator'!D77 -> 8 | V29: QTY | Y29: =IF(Y28="FALSE",IF(X28="45° Std Elbow",VLOOKUP($Y$25,$A$4:$U$18,5),IF(X28="45° Street Elbow",VLOOKUP($Y$25,$A$4:$U$18,6),IF(X28="180° Std Elbow",VLOOKUP($Y$25,$A$4:$U$18,7),IF(X28="Flow Through Branch",VLOOKUP($Y$25,$A$4:$U$18,8),IF(X28="Straight-Through Flow No Reduction",VLOOKUP($Y$25,$A$4:$U$18,9),IF(X28="Straight-Through Flow Reduced 1/4",VLOOKUP($Y$25,$A$4:$U$18,10),"FALSE"))))))) -> FALSE | Z29: 2nd Attempt | AA29: ='R-410A_Calculator'!D67 -> 8 | AB29: QTY
B30: =IF(B29="FALSE",IF(A28="Straight-Through Flow Reduced 1/2",VLOOKUP($B$25,$A$4:$U$18,11),IF(A28="Globe or Solenoid Valve",VLOOKUP($B$25,$A$4:$U$18,12),IF(A28="60° Wye Valve",VLOOKUP($B$25,$A$4:$U$18,13),IF(A28="45° Wye Valve",VLOOKUP($B$25,$A$4:$U$18,14),IF(A28="Angle Valve",VLOOKUP($B$25,$A$4:$U$18,15),IF(A28="Gate Valve",VLOOKUP($B$25,$A$4:$U$18,16),"FALSE"))))))) -> FALSE | C30: 3rd Attempt | D30: =IF(D28="Enter Value","No Data",D28*D29) -> 12 | E30: FT | G30: =IF(G29="FALSE",IF(F28="Straight-Through Flow Reduced 1/2",VLOOKUP($B$25,$A$4:$U$18,11),IF(F28="Globe or Solenoid Valve",VLOOKUP($B$25,$A$4:$U$18,12),IF(F28="60° Wye Valve",VLOOKUP($B$25,$A$4:$U$18,13),IF(F28="45° Wye Valve",VLOOKUP($B$25,$A$4:$U$18,14),IF(F28="Angle Valve",VLOOKUP($B$25,$A$4:$U$18,15),IF(F28="Gate Valve",VLOOKUP($B$25,$A$4:$U$18,16),"FALSE"))))))) -> FALSE | H30: 3rd Attempt | I30: =IF(I28="Enter Value","No Data",I28*I29) -> 1.1 | J30: FT | M30: =IF(M29="FALSE",IF(L28="Straight-Through Flow Reduced 1/2",VLOOKUP($M$25,$A$4:$U$18,11),IF(L28="Globe or Solenoid Valve",VLOOKUP($M$25,$A$4:$U$18,12),IF(L28="60° Wye Valve",VLOOKUP($M$25,$A$4:$U$18,13),IF(L28="45° Wye Valve",VLOOKUP($M$25,$A$4:$U$18,14),IF(L28="Angle Valve",VLOOKUP($M$25,$A$4:$U$18,15),IF(L28="Gate Valve",VLOOKUP($M$25,$A$4:$U$18,16),"FALSE"))))))) -> FALSE | N30: 3rd Attempt | O30: =IF(O28="Enter Value","No Data",O28*O29) -> 26.4 | P30: FT | S30: =IF(S29="FALSE",IF(R28="Straight-Through Flow Reduced 1/2",VLOOKUP($S$25,$A$4:$U$18,11),IF(R28="Globe or Solenoid Valve",VLOOKUP($S$25,$A$4:$U$18,12),IF(R28="60° Wye Valve",VLOOKUP($S$25,$A$4:$U$18,13),IF(R28="45° Wye Valve",VLOOKUP($S$25,$A$4:$U$18,14),IF(R28="Angle Valve",VLOOKUP($S$25,$A$4:$U$18,15),IF(R28="Gate Valve",VLOOKUP($S$25,$A$4:$U$18,16),"FALSE"))))))) -> FALSE | T30: 3rd Attempt | U30: =IF(U28="Enter Value","No Data",U28*U29) -> 26.4 | V30: FT | Y30: =IF(Y29="FALSE",IF(X28="Straight-Through Flow Reduced 1/2",VLOOKUP($Y$25,$A$4:$U$18,11),IF(X28="Globe or Solenoid Valve",VLOOKUP($Y$25,$A$4:$U$18,12),IF(X28="60° Wye Valve",VLOOKUP($Y$25,$A$4:$U$18,13),IF(X28="45° Wye Valve",VLOOKUP($Y$25,$A$4:$U$18,14),IF(X28="Angle Valve",VLOOKUP($Y$25,$A$4:$U$18,15),IF(X28="Gate Valve",VLOOKUP($Y$25,$A$4:$U$18,16),"FALSE"))))))) -> FALSE | Z30: 3rd Attempt | AA30: =IF(AA28="Enter Value","No Data",AA28*AA29) -> 11.2 | AB30: FT
B31: =IF(B30="FALSE",IF(A28="Swing Check",VLOOKUP($B$25,$A$4:$U$18,17),IF(A28="Sight Glass",VLOOKUP($B$25,$A$4:$U$18,18),IF(A28="Filter Drier",VLOOKUP($B$25,$A$4:$U$18,19),IF(A28="Suction Filter",VLOOKUP($B$25,$A$4:$U$18,20),IF(A28="Other",VLOOKUP($B$25,$A$4:$U$18,21),"FALSE")))))) -> FALSE | C31: 4th Attempt | G31: =IF(G30="FALSE",IF(F28="Swing Check",VLOOKUP($B$25,$A$4:$U$18,17),IF(F28="Sight Glass",VLOOKUP($B$25,$A$4:$U$18,18),IF(F28="Filter Drier",VLOOKUP($B$25,$A$4:$U$18,19),IF(F28="Suction Filter",VLOOKUP($B$25,$A$4:$U$18,20),IF(F28="Other",VLOOKUP($B$25,$A$4:$U$18,21),"FALSE")))))) -> 1.1 | H31: 4th Attempt | M31: =IF(M30="FALSE",IF(L28="Swing Check",VLOOKUP($M$25,$A$4:$U$18,17),IF(L28="Sight Glass",VLOOKUP($M$25,$A$4:$U$18,18),IF(L28="Filter Drier",VLOOKUP($M$25,$A$4:$U$18,19),IF(L28="Suction Filter",VLOOKUP($M$25,$A$4:$U$18,20),IF(L28="Other",VLOOKUP($M$25,$A$4:$U$18,21),"FALSE")))))) -> FALSE | N31: 4th Attempt | S31: =IF(S30="FALSE",IF(R28="Swing Check",VLOOKUP($S$25,$A$4:$U$18,17),IF(R28="Sight Glass",VLOOKUP($S$25,$A$4:$U$18,18),IF(R28="Filter Drier",VLOOKUP($S$25,$A$4:$U$18,19),IF(R28="Suction Filter",VLOOKUP($S$25,$A$4:$U$18,20),IF(R28="Other",VLOOKUP($S$25,$A$4:$U$18,21),"FALSE")))))) -> FALSE | T31: 4th Attempt | Y31: =IF(Y30="FALSE",IF(X28="Swing Check",VLOOKUP($Y$25,$A$4:$U$18,17),IF(X28="Sight Glass",VLOOKUP($Y$25,$A$4:$U$18,18),IF(X28="Filter Drier",VLOOKUP($Y$25,$A$4:$U$18,19),IF(X28="Suction Filter",VLOOKUP($Y$25,$A$4:$U$18,20),IF(X28="Other",VLOOKUP($Y$25,$A$4:$U$18,21),"FALSE")))))) -> FALSE | Z31: 4th Attempt
A33: 2nd Component | F33: 5th Component | L33: 2nd Component | R33: 2nd Component | X33: 2nd Component
A34: ='R-410A_Calculator'!C21 -> 45° Std Elbow | B34: =IF(A34="Click here to select fitting.",0,IF(A34="90° Std Elbow",VLOOKUP($B$25,$A$4:$U$18,2),IF(A34="90° Long Radius Elbow",VLOOKUP($B$25,$A$4:$U$18,3),IF(A34="90° Street Elbow",VLOOKUP($B$25,$A$4:$U$18,4),"FALSE")))) -> FALSE | C34: 1st Attempt | D34: =IF(MAX(B34:B37)<0,"Enter Value",MAX(B34:B37)) -> 0.75 | E34: FT | F34: ='R-410A_Calculator'!C24 -> Filter Drier | G34: =IF(F34="Click here to select fitting.",0,IF(F34="90° Std Elbow",VLOOKUP($B$25,$A$4:$U$18,2),IF(F34="90° Long Radius Elbow",VLOOKUP($B$25,$A$4:$U$18,3),IF(F34="90° Street Elbow",VLOOKUP($B$25,$A$4:$U$18,4),"FALSE")))) -> FALSE | H34: 1st Attempt | I34: =IF(MAX(G34:G37)<0,"Enter Value",MAX(G34:G37)) -> 13.5 | J34: FT | L34: ='R-410A_Calculator'!C36 -> 45° Std Elbow | M34: =IF(L34="Click here to select fitting.",0,IF(L34="90° Std Elbow",VLOOKUP($M$25,$A$4:$U$18,2),IF(L34="90° Long Radius Elbow",VLOOKUP($M$25,$A$4:$U$18,3),IF(L34="90° Street Elbow",VLOOKUP($M$25,$A$4:$U$18,4),"FALSE")))) -> FALSE | N34: 1st Attempt | O34: =IF(MAX(M34:M37)<0,"Enter Value",MAX(M34:M37)) -> 1.7 | P34: FT | R34: ='R-410A_Calculator'!C78 -> 45° Std Elbow | S34: =IF(R34="Click here to select fitting.",0,IF(R34="90° Std Elbow",VLOOKUP($S$25,$A$4:$U$18,2),IF(R34="90° Long Radius Elbow",VLOOKUP($S$25,$A$4:$U$18,3),IF(R34="90° Street Elbow",VLOOKUP($S$25,$A$4:$U$18,4),"FALSE")))) -> FALSE | T34: 1st Attempt | U34: =IF(MAX(S34:S37)<0,"Enter Value",MAX(S34:S37)) -> 1.7 | V34: FT | X34: ='R-410A_Calculator'!C68 -> 45° Std Elbow | Y34: =IF(X34="Click here to select fitting.",0,IF(X34="90° Std Elbow",VLOOKUP($Y$25,$A$4:$U$18,2),IF(X34="90° Long Radius Elbow",VLOOKUP($Y$25,$A$4:$U$18,3),IF(X34="90° Street Elbow",VLOOKUP($Y$25,$A$4:$U$18,4),"FALSE")))) -> FALSE | Z34: 1st Attempt | AA34: =IF(MAX(Y34:Y37)<0,"Enter Value",MAX(Y34:Y37)) -> 0.7 | AB34: FT
B35: =IF(B34="FALSE",IF(A34="45° Std Elbow",VLOOKUP($B$25,$A$4:$U$18,5),IF(A34="45° Street Elbow",VLOOKUP($B$25,$A$4:$U$18,6),IF(A34="180° Std Elbow",VLOOKUP($B$25,$A$4:$U$18,7),IF(A34="Flow Through Branch",VLOOKUP($B$25,$A$4:$U$18,8),IF(A34="Straight-Through Flow No Reduction",VLOOKUP($B$25,$A$4:$U$18,9),IF(A34="Straight-Through Flow Reduced 1/4",VLOOKUP($B$25,$A$4:$U$18,10),"FALSE"))))))) -> 0.75 | C35: 2nd Attempt | D35: ='R-410A_Calculator'!D21 -> 0 | E35: QTY | G35: =IF(G34="FALSE",IF(F34="45° Std Elbow",VLOOKUP($B$25,$A$4:$U$18,5),IF(F34="45° Street Elbow",VLOOKUP($B$25,$A$4:$U$18,6),IF(F34="180° Std Elbow",VLOOKUP($B$25,$A$4:$U$18,7),IF(F34="Flow Through Branch",VLOOKUP($B$25,$A$4:$U$18,8),IF(F34="Straight-Through Flow No Reduction",VLOOKUP($B$25,$A$4:$U$18,9),IF(F34="Straight-Through Flow Reduced 1/4",VLOOKUP($B$25,$A$4:$U$18,10),"FALSE"))))))) -> FALSE | H35: 2nd Attempt | I35: ='R-410A_Calculator'!D24 -> 1 | J35: QTY | M35: =IF(M34="FALSE",IF(L34="45° Std Elbow",VLOOKUP($M$25,$A$4:$U$18,5),IF(L34="45° Street Elbow",VLOOKUP($M$25,$A$4:$U$18,6),IF(L34="180° Std Elbow",VLOOKUP($M$25,$A$4:$U$18,7),IF(L34="Flow Through Branch",VLOOKUP($M$25,$A$4:$U$18,8),IF(L34="Straight-Through Flow No Reduction",VLOOKUP($M$25,$A$4:$U$18,9),IF(L34="Straight-Through Flow Reduced 1/4",VLOOKUP($M$25,$A$4:$U$18,10),"FALSE"))))))) -> 1.7 | N35: 2nd Attempt | O35: ='R-410A_Calculator'!D36 -> 0 | P35: QTY | S35: =IF(S34="FALSE",IF(R34="45° Std Elbow",VLOOKUP($S$25,$A$4:$U$18,5),IF(R34="45° Street Elbow",VLOOKUP($S$25,$A$4:$U$18,6),IF(R34="180° Std Elbow",VLOOKUP($S$25,$A$4:$U$18,7),IF(R34="Flow Through Branch",VLOOKUP($S$25,$A$4:$U$18,8),IF(R34="Straight-Through Flow No Reduction",VLOOKUP($S$25,$A$4:$U$18,9),IF(R34="Straight-Through Flow Reduced 1/4",VLOOKUP($S$25,$A$4:$U$18,10),"FALSE"))))))) -> 1.7 | T35: 2nd Attempt | U35: ='R-410A_Calculator'!D78 -> 0 | V35: QTY | Y35: =IF(Y34="FALSE",IF(X34="45° Std Elbow",VLOOKUP($Y$25,$A$4:$U$18,5),IF(X34="45° Street Elbow",VLOOKUP($Y$25,$A$4:$U$18,6),IF(X34="180° Std Elbow",VLOOKUP($Y$25,$A$4:$U$18,7),IF(X34="Flow Through Branch",VLOOKUP($Y$25,$A$4:$U$18,8),IF(X34="Straight-Through Flow No Reduction",VLOOKUP($Y$25,$A$4:$U$18,9),IF(X34="Straight-Through Flow Reduced 1/4",VLOOKUP($Y$25,$A$4:$U$18,10),"FALSE"))))))) -> 0.7 | Z35: 2nd Attempt | AA35: ='R-410A_Calculator'!D68 -> 0 | AB35: QTY
B36: =IF(B35="FALSE",IF(A34="Straight-Through Flow Reduced 1/2",VLOOKUP($B$25,$A$4:$U$18,11),IF(A34="Globe or Solenoid Valve",VLOOKUP($B$25,$A$4:$U$18,12),IF(A34="60° Wye Valve",VLOOKUP($B$25,$A$4:$U$18,13),IF(A34="45° Wye Valve",VLOOKUP($B$25,$A$4:$U$18,14),IF(A34="Angle Valve",VLOOKUP($B$25,$A$4:$U$18,15),IF(A34="Gate Valve",VLOOKUP($B$25,$A$4:$U$18,16),"FALSE"))))))) -> FALSE | C36: 3rd Attempt | D36: =IF(D34="Enter Value","No Data",D34*D35) -> 0 | E36: FT | G36: =IF(G35="FALSE",IF(F34="Straight-Through Flow Reduced 1/2",VLOOKUP($B$25,$A$4:$U$18,11),IF(F34="Globe or Solenoid Valve",VLOOKUP($B$25,$A$4:$U$18,12),IF(F34="60° Wye Valve",VLOOKUP($B$25,$A$4:$U$18,13),IF(F34="45° Wye Valve",VLOOKUP($B$25,$A$4:$U$18,14),IF(F34="Angle Valve",VLOOKUP($B$25,$A$4:$U$18,15),IF(F34="Gate Valve",VLOOKUP($B$25,$A$4:$U$18,16),"FALSE"))))))) -> FALSE | H36: 3rd Attempt | I36: =IF(I34="Enter Value","No Data",I34*I35) -> 13.5 | J36: FT | M36: =IF(M35="FALSE",IF(L34="Straight-Through Flow Reduced 1/2",VLOOKUP($M$25,$A$4:$U$18,11),IF(L34="Globe or Solenoid Valve",VLOOKUP($M$25,$A$4:$U$18,12),IF(L34="60° Wye Valve",VLOOKUP($M$25,$A$4:$U$18,13),IF(L34="45° Wye Valve",VLOOKUP($M$25,$A$4:$U$18,14),IF(L34="Angle Valve",VLOOKUP($M$25,$A$4:$U$18,15),IF(L34="Gate Valve",VLOOKUP($M$25,$A$4:$U$18,16),"FALSE"))))))) -> FALSE | N36: 3rd Attempt | O36: =IF(O34="Enter Value","No Data",O34*O35) -> 0 | P36: FT | S36: =IF(S35="FALSE",IF(R34="Straight-Through Flow Reduced 1/2",VLOOKUP($S$25,$A$4:$U$18,11),IF(R34="Globe or Solenoid Valve",VLOOKUP($S$25,$A$4:$U$18,12),IF(R34="60° Wye Valve",VLOOKUP($S$25,$A$4:$U$18,13),IF(R34="45° Wye Valve",VLOOKUP($S$25,$A$4:$U$18,14),IF(R34="Angle Valve",VLOOKUP($S$25,$A$4:$U$18,15),IF(R34="Gate Valve",VLOOKUP($S$25,$A$4:$U$18,16),"FALSE"))))))) -> FALSE | T36: 3rd Attempt | U36: =IF(U34="Enter Value","No Data",U34*U35) -> 0 | V36: FT | Y36: =IF(Y35="FALSE",IF(X34="Straight-Through Flow Reduced 1/2",VLOOKUP($Y$25,$A$4:$U$18,11),IF(X34="Globe or Solenoid Valve",VLOOKUP($Y$25,$A$4:$U$18,12),IF(X34="60° Wye Valve",VLOOKUP($Y$25,$A$4:$U$18,13),IF(X34="45° Wye Valve",VLOOKUP($Y$25,$A$4:$U$18,14),IF(X34="Angle Valve",VLOOKUP($Y$25,$A$4:$U$18,15),IF(X34="Gate Valve",VLOOKUP($Y$25,$A$4:$U$18,16),"FALSE"))))))) -> FALSE | Z36: 3rd Attempt | AA36: =IF(AA34="Enter Value","No Data",AA34*AA35) -> 0 | AB36: FT
B37: =IF(B36="FALSE",IF(A34="Swing Check",VLOOKUP($B$25,$A$4:$U$18,17),IF(A34="Sight Glass",VLOOKUP($B$25,$A$4:$U$18,18),IF(A34="Filter Drier",VLOOKUP($B$25,$A$4:$U$18,19),IF(A34="Suction Filter",VLOOKUP($B$25,$A$4:$U$18,20),IF(A34="Other",VLOOKUP($B$25,$A$4:$U$18,21),"FALSE")))))) -> FALSE | C37: 4th Attempt | G37: =IF(G36="FALSE",IF(F34="Swing Check",VLOOKUP($B$25,$A$4:$U$18,17),IF(F34="Sight Glass",VLOOKUP($B$25,$A$4:$U$18,18),IF(F34="Filter Drier",VLOOKUP($B$25,$A$4:$U$18,19),IF(F34="Suction Filter",VLOOKUP($B$25,$A$4:$U$18,20),IF(F34="Other",VLOOKUP($B$25,$A$4:$U$18,21),"FALSE")))))) -> 13.5 | H37: 4th Attempt | M37: =IF(M36="FALSE",IF(L34="Swing Check",VLOOKUP($M$25,$A$4:$U$18,17),IF(L34="Sight Glass",VLOOKUP($M$25,$A$4:$U$18,18),IF(L34="Filter Drier",VLOOKUP($M$25,$A$4:$U$18,19),IF(L34="Suction Filter",VLOOKUP($M$25,$A$4:$U$18,20),IF(L34="Other",VLOOKUP($M$25,$A$4:$U$18,21),"FALSE")))))) -> FALSE | N37: 4th Attempt | S37: =IF(S36="FALSE",IF(R34="Swing Check",VLOOKUP($S$25,$A$4:$U$18,17),IF(R34="Sight Glass",VLOOKUP($S$25,$A$4:$U$18,18),IF(R34="Filter Drier",VLOOKUP($S$25,$A$4:$U$18,19),IF(R34="Suction Filter",VLOOKUP($S$25,$A$4:$U$18,20),IF(R34="Other",VLOOKUP($S$25,$A$4:$U$18,21),"FALSE")))))) -> FALSE | T37: 4th Attempt | Y37: =IF(Y36="FALSE",IF(X34="Swing Check",VLOOKUP($Y$25,$A$4:$U$18,17),IF(X34="Sight Glass",VLOOKUP($Y$25,$A$4:$U$18,18),IF(X34="Filter Drier",VLOOKUP($Y$25,$A$4:$U$18,19),IF(X34="Suction Filter",VLOOKUP($Y$25,$A$4:$U$18,20),IF(X34="Other",VLOOKUP($Y$25,$A$4:$U$18,21),"FALSE")))))) -> FALSE | Z37: 4th Attempt
A39: 3rd Component | F39: 6th Component | L39: 3rd Component | R39: 3rd Component | X39: 3rd Component
A40: ='R-410A_Calculator'!C22 -> Globe or Solenoid Valve | B40: =IF(A40="Click here to select fitting.",0,IF(A40="90° Std Elbow",VLOOKUP($B$25,$A$4:$U$18,2),IF(A40="90° Long Radius Elbow",VLOOKUP($B$25,$A$4:$U$18,3),IF(A40="90° Street Elbow",VLOOKUP($B$25,$A$4:$U$18,4),"FALSE")))) -> FALSE | C40: 1st Attempt | D40: =IF(MAX(B40:B43)<0,"Enter Value",MAX(B40:B43)) -> 17.5 | E40: FT | F40: ='R-410A_Calculator'!C25 -> Click here to select fitting. | G40: =IF(F40="Click here to select fitting.",0,IF(F40="90° Std Elbow",VLOOKUP($B$25,$A$4:$U$18,2),IF(F40="90° Long Radius Elbow",VLOOKUP($B$25,$A$4:$U$18,3),IF(F40="90° Street Elbow",VLOOKUP($B$25,$A$4:$U$18,4),"FALSE")))) -> 0 | H40: 1st Attempt | I40: =IF(MAX(G40:G43)<0,"Enter Value",MAX(G40:G43)) -> 0 | J40: FT | L40: ='R-410A_Calculator'!C37 -> Click here to select fitting. | M40: =IF(L40="Click here to select fitting.",0,IF(L40="90° Std Elbow",VLOOKUP($M$25,$A$4:$U$18,2),IF(L40="90° Long Radius Elbow",VLOOKUP($B$25,$A$4:$U$18,3),IF(L40="90° Street Elbow",VLOOKUP($M$25,$A$4:$U$18,4),"FALSE")))) -> 0 | N40: 1st Attempt | O40: =IF(MAX(M40:M43)<0,"Enter Value",MAX(M40:M43)) -> 0 | P40: FT | R40: ='R-410A_Calculator'!C79 -> Click here to select fitting. | S40: =IF(R40="Click here to select fitting.",0,IF(R40="90° Std Elbow",VLOOKUP($S$25,$A$4:$U$18,2),IF(R40="90° Long Radius Elbow",VLOOKUP($S$25,$A$4:$U$18,3),IF(R40="90° Street Elbow",VLOOKUP($S$25,$A$4:$U$18,4),"FALSE")))) -> 0 | T40: 1st Attempt | U40: =IF(MAX(S40:S43)<0,"Enter Value",MAX(S40:S43)) -> 0 | V40: FT | X40: ='R-410A_Calculator'!C69 -> Globe or Solenoid Valve | Y40: =IF(X40="Click here to select fitting.",0,IF(X40="90° Std Elbow",VLOOKUP($Y$25,$A$4:$U$18,2),IF(X40="90° Long Radius Elbow",VLOOKUP($Y$25,$A$4:$U$18,3),IF(X40="90° Street Elbow",VLOOKUP($Y$25,$A$4:$U$18,4),"FALSE")))) -> FALSE | Z40: 1st Attempt | AA40: =IF(MAX(Y40:Y43)<0,"Enter Value",MAX(Y40:Y43)) -> 17 | AB40: FT
B41: =IF(B40="FALSE",IF(A40="45° Std Elbow",VLOOKUP($B$25,$A$4:$U$18,5),IF(A40="45° Street Elbow",VLOOKUP($B$25,$A$4:$U$18,6),IF(A40="180° Std Elbow",VLOOKUP($B$25,$A$4:$U$18,7),IF(A40="Flow Through Branch",VLOOKUP($B$25,$A$4:$U$18,8),IF(A40="Straight-Through Flow No Reduction",VLOOKUP($B$25,$A$4:$U$18,9),IF(A40="Straight-Through Flow Reduced 1/4",VLOOKUP($B$25,$A$4:$U$18,10),"FALSE"))))))) -> FALSE | C41: 2nd Attempt | D41: ='R-410A_Calculator'!D22 -> 1 | E41: QTY | G41: =IF(G40="FALSE",IF(F40="45° Std Elbow",VLOOKUP($B$25,$A$4:$U$18,5),IF(F40="45° Street Elbow",VLOOKUP($B$25,$A$4:$U$18,6),IF(F40="180° Std Elbow",VLOOKUP($B$25,$A$4:$U$18,7),IF(F40="Flow Through Branch",VLOOKUP($B$25,$A$4:$U$18,8),IF(F40="Straight-Through Flow No Reduction",VLOOKUP($B$25,$A$4:$U$18,9),IF(F40="Straight-Through Flow Reduced 1/4",VLOOKUP($B$25,$A$4:$U$18,10),"FALSE"))))))) -> FALSE | H41: 2nd Attempt | I41: ='R-410A_Calculator'!D25 -> 0 | J41: QTY | M41: =IF(M40="FALSE",IF(L40="45° Std Elbow",VLOOKUP($M$25,$A$4:$U$18,5),IF(L40="45° Street Elbow",VLOOKUP($M$25,$A$4:$U$18,6),IF(L40="180° Std Elbow",VLOOKUP($M$25,$A$4:$U$18,7),IF(L40="Flow Through Branch",VLOOKUP($M$25,$A$4:$U$18,8),IF(L40="Straight-Through Flow No Reduction",VLOOKUP($M$25,$A$4:$U$18,9),IF(L40="Straight-Through Flow Reduced 1/4",VLOOKUP($M$25,$A$4:$U$18,10),"FALSE"))))))) -> FALSE | N41: 2nd Attempt | O41: ='R-410A_Calculator'!D37 -> 0 | P41: QTY | S41: =IF(S40="FALSE",IF(R40="45° Std Elbow",VLOOKUP($S$25,$A$4:$U$18,5),IF(R40="45° Street Elbow",VLOOKUP($S$25,$A$4:$U$18,6),IF(R40="180° Std Elbow",VLOOKUP($S$25,$A$4:$U$18,7),IF(R40="Flow Through Branch",VLOOKUP($S$25,$A$4:$U$18,8),IF(R40="Straight-Through Flow No Reduction",VLOOKUP($S$25,$A$4:$U$18,9),IF(R40="Straight-Through Flow Reduced 1/4",VLOOKUP($S$25,$A$4:$U$18,10),"FALSE"))))))) -> FALSE | T41: 2nd Attempt | U41: ='R-410A_Calculator'!D79 -> 0 | V41: QTY | Y41: =IF(Y40="FALSE",IF(X40="45° Std Elbow",VLOOKUP($Y$25,$A$4:$U$18,5),IF(X40="45° Street Elbow",VLOOKUP($Y$25,$A$4:$U$18,6),IF(X40="180° Std Elbow",VLOOKUP($Y$25,$A$4:$U$18,7),IF(X40="Flow Through Branch",VLOOKUP($Y$25,$A$4:$U$18,8),IF(X40="Straight-Through Flow No Reduction",VLOOKUP($Y$25,$A$4:$U$18,9),IF(X40="Straight-Through Flow Reduced 1/4",VLOOKUP($Y$25,$A$4:$U$18,10),"FALSE"))))))) -> FALSE | Z41: 2nd Attempt | AA41: ='R-410A_Calculator'!D69 -> 1 | AB41: QTY
B42: =IF(B41="FALSE",IF(A40="Straight-Through Flow Reduced 1/2",VLOOKUP($B$25,$A$4:$U$18,11),IF(A40="Globe or Solenoid Valve",VLOOKUP($B$25,$A$4:$U$18,12),IF(A40="60° Wye Valve",VLOOKUP($B$25,$A$4:$U$18,13),IF(A40="45° Wye Valve",VLOOKUP($B$25,$A$4:$U$18,14),IF(A40="Angle Valve",VLOOKUP($B$25,$A$4:$U$18,15),IF(A40="Gate Valve",VLOOKUP($B$25,$A$4:$U$18,16),"FALSE"))))))) -> 17.5 | C42: 3rd Attempt | D42: =IF(D40="Enter Value","No Data",D40*D41) -> 17.5 | E42: FT | G42: =IF(G41="FALSE",IF(F40="Straight-Through Flow Reduced 1/2",VLOOKUP($B$25,$A$4:$U$18,11),IF(F40="Globe or Solenoid Valve",VLOOKUP($B$25,$A$4:$U$18,12),IF(F40="60° Wye Valve",VLOOKUP($B$25,$A$4:$U$18,13),IF(F40="45° Wye Valve",VLOOKUP($B$25,$A$4:$U$18,14),IF(F40="Angle Valve",VLOOKUP($B$25,$A$4:$U$18,15),IF(F40="Gate Valve",VLOOKUP($B$25,$A$4:$U$18,16),"FALSE"))))))) -> FALSE | H42: 3rd Attempt | I42: =IF(I40="Enter Value","No Data",I40*I41) -> 0 | J42: FT | M42: =IF(M41="FALSE",IF(L40="Straight-Through Flow Reduced 1/2",VLOOKUP($M$25,$A$4:$U$18,11),IF(L40="Globe or Solenoid Valve",VLOOKUP($M$25,$A$4:$U$18,12),IF(L40="60° Wye Valve",VLOOKUP($M$25,$A$4:$U$18,13),IF(L40="45° Wye Valve",VLOOKUP($M$25,$A$4:$U$18,14),IF(L40="Angle Valve",VLOOKUP($M$25,$A$4:$U$18,15),IF(L40="Gate Valve",VLOOKUP($M$25,$A$4:$U$18,16),"FALSE"))))))) -> FALSE | N42: 3rd Attempt | O42: =IF(O40="Enter Value","No Data",O40*O41) -> 0 | P42: FT | S42: =IF(S41="FALSE",IF(R40="Straight-Through Flow Reduced 1/2",VLOOKUP($S$25,$A$4:$U$18,11),IF(R40="Globe or Solenoid Valve",VLOOKUP($S$25,$A$4:$U$18,12),IF(R40="60° Wye Valve",VLOOKUP($S$25,$A$4:$U$18,13),IF(R40="45° Wye Valve",VLOOKUP($S$25,$A$4:$U$18,14),IF(R40="Angle Valve",VLOOKUP($S$25,$A$4:$U$18,15),IF(R40="Gate Valve",VLOOKUP($S$25,$A$4:$U$18,16),"FALSE"))))))) -> FALSE | T42: 3rd Attempt | U42: =IF(U40="Enter Value","No Data",U40*U41) -> 0 | V42: FT | Y42: =IF(Y41="FALSE",IF(X40="Straight-Through Flow Reduced 1/2",VLOOKUP($Y$25,$A$4:$U$18,11),IF(X40="Globe or Solenoid Valve",VLOOKUP($Y$25,$A$4:$U$18,12),IF(X40="60° Wye Valve",VLOOKUP($Y$25,$A$4:$U$18,13),IF(X40="45° Wye Valve",VLOOKUP($Y$25,$A$4:$U$18,14),IF(X40="Angle Valve",VLOOKUP($Y$25,$A$4:$U$18,15),IF(X40="Gate Valve",VLOOKUP($Y$25,$A$4:$U$18,16),"FALSE"))))))) -> 17 | Z42: 3rd Attempt | AA42: =IF(AA40="Enter Value","No Data",AA40*AA41) -> 17 | AB42: FT
B43: =IF(B42="FALSE",IF(A40="Swing Check",VLOOKUP($B$25,$A$4:$U$18,17),IF(A40="Sight Glass",VLOOKUP($B$25,$A$4:$U$18,18),IF(A40="Filter Drier",VLOOKUP($B$25,$A$4:$U$18,19),IF(A40="Suction Filter",VLOOKUP($B$25,$A$4:$U$18,20),IF(A40="Other",VLOOKUP($B$25,$A$4:$U$18,21),"FALSE")))))) -> FALSE | C43: 4th Attempt | G43: =IF(G42="FALSE",IF(F40="Swing Check",VLOOKUP($B$25,$A$4:$U$18,17),IF(F40="Sight Glass",VLOOKUP($B$25,$A$4:$U$18,18),IF(F40="Filter Drier",VLOOKUP($B$25,$A$4:$U$18,19),IF(F40="Suction Filter",VLOOKUP($B$25,$A$4:$U$18,20),IF(F40="Other",VLOOKUP($B$25,$A$4:$U$18,21),"FALSE")))))) -> FALSE | H43: 4th Attempt | M43: =IF(M42="FALSE",IF(L40="Swing Check",VLOOKUP($M$25,$A$4:$U$18,17),IF(L40="Sight Glass",VLOOKUP($M$25,$A$4:$U$18,18),IF(L40="Filter Drier",VLOOKUP($M$25,$A$4:$U$18,19),IF(L40="Suction Filter",VLOOKUP($M$25,$A$4:$U$18,20),IF(L40="Other",VLOOKUP($M$25,$A$4:$U$18,21),"FALSE")))))) -> FALSE | N43: 4th Attempt | S43: =IF(S42="FALSE",IF(R40="Swing Check",VLOOKUP($S$25,$A$4:$U$18,17),IF(R40="Sight Glass",VLOOKUP($S$25,$A$4:$U$18,18),IF(R40="Filter Drier",VLOOKUP($S$25,$A$4:$U$18,19),IF(R40="Suction Filter",VLOOKUP($S$25,$A$4:$U$18,20),IF(R40="Other",VLOOKUP($S$25,$A$4:$U$18,21),"FALSE")))))) -> FALSE | T43: 4th Attempt | Y43: =IF(Y42="FALSE",IF(X40="Swing Check",VLOOKUP($Y$25,$A$4:$U$18,17),IF(X40="Sight Glass",VLOOKUP($Y$25,$A$4:$U$18,18),IF(X40="Filter Drier",VLOOKUP($Y$25,$A$4:$U$18,19),IF(X40="Suction Filter",VLOOKUP($Y$25,$A$4:$U$18,20),IF(X40="Other",VLOOKUP($Y$25,$A$4:$U$18,21),"FALSE")))))) -> FALSE | Z43: 4th Attempt

Sheet R-410A_Min_Suction_Riser_Cap
A1: 2006 ASHRAE Handbook Refrigeration | F1: Table Data | H1: Inputs | J1: Calculated Data
A3: Table 12 (App Guide) Minimum Refrigeration Capacity in Tons for Oil Entrainment up Suction Risers
A4: Saturated Suction Temperature | B4: Suction Superheat | C4: Pipe O.D. (Inches)
C5: 0.5 | D5: 0.625 | E5: 0.75 | F5: 0.875 | G5: 1.125 | H5: 1.375 | I5: 1.625 | J5: 2.125 | K5: 2.625 | L5: 3.125 | M5: 3.625 | N5: 4.125
C6: Area (in2)
A7: oF | B7: oF | C7: 0.146 | D7: 0.233 | E7: 0.348 | F7: 0.484 | G7: 0.825 | H7: 1.256 | I7: 1.78 | J7: 3.094 | K7: 4.77 | L7: 6.812 | M7: 9.213 | N7: 11.97
A8: 0 | B8: 10 | C8: 0.167 | D8: 0.317 | E8: 0.542 | F8: 0.833 | G8: 1.67 | H8: 2.92 | I8: 4.58 | J8: 9.58 | K8: 17.17 | L8: 26.67 | M8: 40 | N8: 55.83
A9: 20 | B9: 10 | C9: 0.192 | D9: 0.363 | E9: 0.667 | F9: 0.958 | G9: 1.96 | H9: 3.42 | I9: 5.33 | J9: 11.08 | K9: 19.58 | L9: 30.83 | M9: 45.83 | N9: 64.17
A10: 40 | B10: 10 | C10: 0.213 | D10: 0.4 | E10: 0.683 | F10: 1.067 | G10: 2.17 | H10: 3.75 | I10: 6 | J10: 12.42 | K10: 21.67 | L10: 35 | M10: 51.67 | N10: 71.67
A12: Suction Superheat | B12: 10
B13: oF | F13: Min. Suction Riser Capacity - Curve Fit | J13: Info Found Below Table 12 (App Guide) | R13: Min. Suction Riser Capacity - Curve Fit w/Multiplier
A14: Type L Copper, OD | B14: Saturated Suction Temperature, oF | F14: SST | G14: Type L Copper, OD | H14: Superheat | L14: Interpolation of Suction & Discharge Multipliers | T14: Determines Minimum Suction Riser Size | Z14: Determines Suction Riser Capacity
F15: oF | H15: 10 | J15: Condensing Temperature | K15: R-410A | L15: Act. Cond. Temp. | M15: Min # for Interpolation | N15: Max # for Interpolation | O15: Known x's | P15: Known y's Suction | Q15: Suction Riser | T15: Min. Suction Capacity | U15: Look Up Sufficient Suction Line Capacity | V15: Determine Minimum Suction Line Capacity | W15: Corresponding Suction Riser Size, OD | Z15: Table 3 - Curve Fit w/ Suction Multiplier
B16: 0 | C16: 20 | D16: 40 | F16: ='R-410A_Calculator'!D12 -> 40 | G16: inches | H16: oF | R16: Suction Riser Capacity | S16: Type L Copper, OD | Z16: Type L Copper, OD | AA16: Suction Line Capacity | AB16: Size of Suction Riser | AC16: Riser Capacity
A17: 0.5 | B17: {=TRANSPOSE(C8:N8)} -> 0.167 | C17: {=TRANSPOSE(C9:N9)} -> 0.192 | D17: {=TRANSPOSE(C10:N10)} -> 0.213 | G17: 0.5 | H17: =-0.000005*F16^2 + 0.0014*F16 + 0.167 -> 0.215 | J17: oF | K17: multiplier | L17: oF | Q17: multiplier | T17: tons
